16 예외처리
===

# 1. 예외처리

## 예외

이 세상에 완벽한 프로그램은 없습니다. 따라서 어떤 프로그램이든지 잘못된 코드, 부정학환 데이터, 예외적인 상황에 의하여 오류가 발생할 수 있다. 예를 들어 0으로 나누는 것과 같은 잘못된 연산을 수행하거나, 배열의 인덱스가 한계를 넘을 수도 있고 네트워크가 다운될 수도 있다. C++에서는 이러한 오류를 예외(exception)라는 이름으로 부른다. 대개의 경우 오류가 발생하면 프로그램이 종료된다. 그러나 무조건 종료하는 것 보다 프로그램에서 오류를 감지하여 우아하게 프로그램을 종료하거나 오류를 처리한 후에 계속 실행할 수 있다면 더 나은 프로그램이 될 수 있다. 이것을 예외 처리(exception handling)라고 한다.

예외를 설명하는 예제로 피자 한 판을 여러 명이 나누어 먹는다고 가정하자. 한 사람이 먹을 수 있는 피자 조각 수를 계산하는 프로그램을 작성해보자.

```c++
#include <iostream>
using namespace std;
int main()
{
	int pizza_slices = 0;
	int persons = -1;
	int slices_per_person=0;

	cout << "피자 조각수를 입력하시오: ";
	cin >> pizza_slices;
	cout << "사람수를 입력하시오: ";
	cin >> persons;
	slices_per_person = pizza_slices / persons;	
	cout << "한사람당 피자는 " << slices_per_person << "입니다." << endl;

	return 0;
}
```

여기서 사람수가 0명이면 오류가 발생하게 된다. 그러면 사람수가 0인지 아닌지 항상 판단해야 한다. 이 문제를 전통적인 오류 처리 방식으로는 다음과 같이 한다.

## 전통적인 오류 처리 방식

전통적인 오류 처리 방식은 if-else를 사용하여 조건을 검사하는 것이다. 일단 사람 수가 0이면 오류 메시지를 출력한다. 사람 수가 0이 아니면 피자 조각 수를 사람 수로 나누어서 출력한다.

```c++
#include <iostream>
using namespace std;
int main()
{
	int pizza_slices = 0;
	int persons = -1;
	int slices_per_person=0;

	cout << "피자 조각수를 입력하시오: ";
	cin >> pizza_slices;
	cout << "사람수를 입력하시오: ";
	cin >> persons;

	if (persons == 0) {
		cout << "사람이 0명 입니다. "<< endl;
	} else {
		slices_per_person = pizza_slices / persons;	
		cout << "한사람당 피자는 " << slices_per_person << "입니다." << endl;
	}
	return 0;
}
```

하지만 이러한 방식의 경우, 검사해야하는 조건이 많아지면 상당히 복잡해지고 동시에 어떤 코드가 정상적인 실행이고 어떤 코드가 오류 처리 코드인지 구별하기 힘들다. 우리의 피자 프로그램에서도 체크 해야 할 것이 더 있다. 먼저 피자 조각이 0개면 계산할 필요가 없으며, 사람의 수는 음수가 될 수 없다. 이것을 다 처리하려면 조건문이 깊어지며 코드가 점점 복잡해진다.

```c++
#include <iostream>
using namespace std;
int main()
{
	int pizza_slices = 0;
	int persons = -1;
	int slices_per_person=0;

	cout << "피자 조각수를 입력하시오: ";
	cin >> pizza_slices;
	cout << "사람수를 입력하시오: ";
	cin >> persons;

    if(pizza_slices < 0){
        cout<<"피자 조각이 음수"<<endl;
    }else{
        if (persons == 0) {
            cout << "사람이 0명 입니다. "<< endl;
        } else if(persons < 0){
            cout<<"사람이 음수입니다."<<endl;
        } else {
            slices_per_person = pizza_slices / persons;	
            cout << "한사람당 피자는 " << slices_per_person << "입니다." << endl;
        }
    }

	return 0;
}
```

그리고 함수 안에서 오류가 발생하면 보통 함수의 반환값으로 오류가 일어났음을 알리게 된다. 하지만 이런 방법은 함수의 반환값을 다른 용도로 사용할 수 없게 한다.

## 버그와 예외

여기서 한 가지 주의할 점은 버그와 예외는 구분되어야 한다. 실행 도중에 버그로 인해서도 실행 오류가 발생할 수 있지만 이러한 버그는 개발 과정에서 모두 수정되어야 한다. C++에서는 버그에 의한 실행 오류도 예외로 취급하지만 진정한 의미에서의 예외는 우리가 예상하였던 상황이 아닌 경우를 의미한다. 

- 파일이 열려있지 않은데 닫으려고 할 때
- 반드시 존재하여야 하는 파일이 없을 때
- 인터넷 서버가 다운되엇을 때
- 정수를 입력하는 곳에서 문자를 입력할 때
- 배열의 인덱스를 벗어날 때

# 2. 예외 처리기

C++에서는 언어 차원에서 예외 처리 형식을 제공한다. C++예외 처리는 try, throw, catch의 키워드를 사용한다. 예외 처리기의 기본 형식은 다음과 같다.

```c++
try{
    //예외가 발생할 수 있는 코드
    if(예외조건)
        throw 예외;
}catch(타입 매개변수){
    //예외를 처리하는 코드
}
```

먼저 try 블록에는 예외가 발생할 가능성이 있는 문장이 들어간다. 만약 예외 조건이 감지되면 throw 문장이 실행되어 예외를 던진다. 보통 예외가 발생되었다는 것을 예외를 던진다고 표현한다. throw 키워드 뒤에 던져질 예외를 적는다. 예외가 던져지면 이 예외를 처리하는 catch문으로 이동한다. 이 경우 throw 문장 밑에 위치한 코드들은 실행되지 않는다. 

catch 블록에서는 던져진 예외를 받아서 처리한다. catch뒤에는 자신이 처리할 수 있는 예외의 타입을 지정하고 그 예외를 처리하기 위한 코드가 들어간다.

피자 예제를 예외 처리를 이용해서 다시 작성해보자.

```c++
#include <iostream>
using namespace std;
int main()
{
	int pizza_slices = 0;
	int persons = -1;
	int slices_per_person=0;

	try 
	{
		cout << "피자 조각수를 입력하시오: ";
		cin >> pizza_slices;
		cout << "사람수를 입력하시오: ";
		cin >> persons;

		if (persons == 0) 
			throw persons;
		slices_per_person = pizza_slices / persons;	
		cout << "한사람당 피자는 " << slices_per_person << "입니다." << endl;
	} 
	catch(int e) 
	{
		cout << "사람이 " << e << " 명 입니다. "<< endl;
	}
	return 0;
}
```

## try/catch 블록에서의 실행 흐름

try/catch 블록에서 예외가 발생하는 경우와 발생하지 않는 경우의 실행 흐름을 비교하여 보자. 먼저 예외가 발생하지 않는 경우에는 catch 블록의 코드는 실행되지 않고 catch 블록의 아래에 있는 코드가 실행된다. 반면에 예외가 발생한 경우에는 catch 블록의 코드가 실행되고 이어서 다음 코드가 실행된다.

## catch 블록의 매개 변수

catch 블록은 함수는 아니지만 매개 변수를 가지고 있다는 점에서 함수와 상당히 유사하다. catch 블록을 흔히 예외 처리기(exception handler)라고 불리는 것에도 알 수 있다. 아래 코드에서 catch 블록의 매개 변수 e의 역할을 살펴보자.

```c++
try{
    문장1;

    if(persons == 0)
        throw persons
    
    문장2;
}catch(int e){
    cout<<"예외 발생"<<endl;
}
```

위의 코드에서 e는 함수의 매개 변수와 같은 역할을 한다. throw 문장에서 던진 값이 바로 매개 변수 e를 통하여 예외 처리기로 전달되는 것이다. 어떤 타입도 가능하므로 다양한 타입을 사용할 수 있다. 예제 코드에서 처럼 정수 타입일 수도 있고 문자열, 만약 예외 정보가 복잡하다면 클래스 타입도 가능하다. 보통 매개 변수는 예외에 대한 추가 정보를 전달한다.

## 타입이 일치되는 예외만 처리된다.

한가지 주의할 점은 throw에서 던진 값의 타입과 catch 블록의 매개 변수 타입이 일치해야만 예외가 처리된다. 예를 들어서 앞의 프로그램에서 예외 처리기 블록이 catch(char e)로 선언되어 있다면 예외가 처리되지 않는다.

```c++
try{
    문장1;

    if(persons == 0)
        throw persons
    
    문장2;
}catch(char e){
    cout<<"예외 발생"<<endl;
}
```

만약 발생하는 모든 예외를 잡고 싶으면 매개 변수를 ...로 표시하면 된다.

```c++
catch(...){
    // 모든 예외를 처리할 수 있다.
}
```

# 3. 예외 전달

예외는 함수 범위를 넘어서 전달될 수 있다. 실제로 만약 함수 안에서 예외가 처리되지 않으면 예외는 상위 함수로 넘어간다. 던져진 예외를 처리할 때 까지 함수 호출 체인을 따라가면서 예외의 타입과 같은 예외 처리기를 찾는다.

```c++
int dividePizza(int slices, int persons);

int main(){
    try{
        dividePizza(slices, persons);   //dividePizza 함수 내부에서 예외를 던지면
                                        //함수 내부 뿐만 아니라 함수 밖에서도 예외 처리를 찾는다.
    }catch(int e){
        cout<<"예외 처리 발생"<<endl;
    }
}

int dividePizza(int slices, int persons){
    if(persons == 0)
        throw persons;
}
```

```c++
#include <iostream>
using namespace std;
int dividePizza(int pizza_slices, int persons);

int main()
{
	int pizza_slices = 0;
	int persons = 0;
	int slices_per_person=0;

	try 
	{
		cout << "피자 조각수를 입력하시오: ";
		cin >> pizza_slices;
		cout << "사람수를 입력하시오: ";
		cin >> persons;
		slices_per_person =dividePizza(pizza_slices, persons);
		cout << "한사람당 피자는 " << slices_per_person << "입니다." << endl;
	} 
	catch(int e) 
	{
		cout << "사람이 " << e << " 명 입니다. "<< endl;
	}
	return 0;
}
int dividePizza(int pizza_slices, int persons)
{
    if (persons == 0) 
        throw persons;
    return  pizza_slices / persons;	
}	
```

만약 함수 내부에서 예외처리를 하고 함수 외부에서도 예외를 전달할려면 다음괕이 catch문에 throw를 넣어주면 된다.

```c++
int dividePizza(int pizza_slices, int persons)
{
    try{
        if (persons == 0) 
            throw persons;
        return  pizza_slices / persons;	
    }catch(int e){
        cout<<"사람이 "<<e<<"명 입니다(dividePizza)"<<endl;
        throw;
    }

}	
```

## 헤더에서 예외 명시

만약 함수 안에서 발생된 예외를 즉시 처리하지 않는다면 예외를 던질 수 있음을 경고해주는 것이 좋다. 이것은 함수 헤더 정의 부분에서 이루어 진다.

```c++
int dividePizza(int pizza_slices, int persons) throw ()				//예외를 던지지 않는다.
int dividePizza(int pizza_slices, int persons) throw (...)			//모든 타입에 대해서 예외를 던진다.
int dividePizza(int pizza_slices, int persons) throw (int)			//int타입의 예외를 던진다.
int dividePizza(int pizza_slices, int persons) throw (int ,double)	//int또는 double타입의 예외를 던진다.
```

함수 헤더에 예외를 던질 수 있다고 명시하는 것이 의무 사항은 아니다. 그렇지만 프로그램의 쉬운 이해를 위하여 명시하는 것이 좋다.

## 만약 예외가 처리되지 않으면

만약에 어떤 함수에서도 예외가 처리되지 않으면 시스템 라이브러리 함수인 abort()가 호출되어서 프로그램을 종료하게 된다.

# 4. 다중 catch 문장

하나의 try 블록에서는 여러 개의 throw 문장을 가질 수 있다. 각각의 throw 문장은 타입이 다른 값을 가질 수 있다. 만약 여러 가지 타입의 값을 처리하려면 여러 개의 catch 블록을 두어야 한다. 예를 들어서 피자 나누기 예제에서 사람의 수가 0이 될 수도 있고 사람 수가 음수가 될 수 도 있다. 이것을 구분하여서 처리하려면 다음과 같이 두 개의 catch 블록을 정의하여야 한다.

```c++
#include <iostream>
using namespace std;

int main()
{
	int pizza_slices = 12;
	int persons = 0;
	int slices_per_person=0;

	try {
		cout << "피자 조각수를 입력하시오: ";
		cin >> pizza_slices;
		cout << "사람수를 입력하시오: ";
		cin >> persons;

		if( persons < 0 ) throw "negative";		// 예외 발생!
		if( persons == 0 ) throw persons;		// 예외 발생!
		slices_per_person = pizza_slices / persons;		
		cout << "한사람당 피자는 " << slices_per_person << "입니다." << endl;
	} 
	catch (const char *e) {
		cout << "오류: 사람수가 " << e << "입니다" << endl;
	}
	catch (int e) {
		cout << "오류: 사람이 " << e << " 명입니다." << endl;
	}
	return 0;
}
```

자세히 보면 알겠지만 같은 타입의 catch문이 여러개 올 수 없기 때문에 부족한 부분이 보인다. 특히 persons이 음수일 때 int형을 사용할 수 없어, 문자열인 "negative"로 던진것을 볼 수 있다.

## 구체적인 예외를 먼저 잡는다.

여러 개의 예외를 잡을 수도 있다. 이런 경우에는 보다 구체적인 예외를 먼저 잡아야한다.

```c++
try{
	input("사람 수 : ");
}catch(TooSmallException e){
	//TooSmallException에 대한 예외만 잡힌다.
}catch(...){
	//TooSmallException를 제외한 나머지 예외들이 잡힌다.
}
```

만약 이것을 반대로 하면 두 번째 catch블록은 아무것도 잡아내지 못한다.

```c++
try{
	input("사람 수 : ");
}catch(...){
	//모든 예외들이 잡힌다.
}catch(TooSmallException e){
	//위에서 모든 예외들이 잡히고 있으므로
	//아무것도 잡히지 않는다.
}
```

따라서 구체적인 예외를 먼저 쓰고 일반적인 예외는 나중에 쓰는 것이 좋다. 즉 catch블록을 사용할 때는 범위가 작은 것에부터 큰 것 순서로 작성해야 한다.

## 중간정검

1. 발생된 예외와 catch 블록의 매개 변수는 어떤 규칙에 의하여 매칭되는가?
2. 어떤 자료형이라도 catch 블록의 매개 변수로 지정할 수 있는가?

# 5. 직접 예외 클래스 만들기

throw 문장은 어떤 타입의 값도 던질 수 있다. 따라서 클래스  타입의 객체도 던질 수 있다. 흔히 예외에 대한 정보를 묶어서 클래스로 정의하고 이 클래스의 객체를 던진다. 또 예외를 나타내는 클래스를 정의하게 되면 예외를 유형별로 분류하여서 정리할 수 있따는 장점도 있따.

예외 클래스도 단지 하나의 클래스에 불과하다. 차이점은 예외 클래스는 예외 처리에 사용된다는 것 뿐이다. 다른 클래스와 전적으로 동일하다. 다음 코드는 예외 클래스를 정의하는 하나의 예를 보여준다. 가장 큰 차이점은 throw 문장이 다음과 같이 객체를 던진다는 점이다.

```c++
throw NoPersonException(persons);
```

NoPersonException(persons)는 NoPersonException 클래스의 생성자를 호출한다. 생성자는 사용자가 입력한 사람 수를 받아서 객체를 생성한다.

```c++
#include <iostream>
using namespace std;


class NoPersonException
{
public:
	NoPersonException();
	NoPersonException(int p) { persons = p; };
	int get_persons() { return persons; };
private:
	int persons;
};

int main()
{
	int pizza_slices = 12;
	int persons = -1;
	int slices_per_person=0;

	try {
		cout << "피자 조각수를 입력하시오: ";
		cin >> pizza_slices;
		cout << "사람수를 입력하시오: ";
		cin >> persons;
		if( persons <= 0 ) throw NoPersonException(persons);		// 예외 발생!
		slices_per_person = pizza_slices / persons;		
		cout << "한사람당 피자는 " << slices_per_person << "입니다." << endl;
	} 
	catch (NoPersonException e) 
	{
		cout << "오류: 사람이 " << e.get_persons() << "명 입니다" << endl;
	}
	return 0;
}
```

## 상속 관계에 있는 예외 클래스

만약에 예외를 나타내는 클래스 간에 상속 관계가 있고 catch 블록에서 레퍼런스 타입으로 예외 객체를 잡는다면 주의하여야 한다. 만약 매개 변수를 부모 클래스의 레퍼런스 타입으로 지정하면 상속에서 학습한 바와 같이 자손 클래스의 객체들을 모두 잡을 수 있다.

예를 들어 간단한 예제를 생각하여 보자. ParentException 클래스와 ChildException 클래스 사이에는 상속 관계가 있다.

```c++
#include <iostream>
using namespace std;

class ParentException
{
public:
	void display() { cout << "ParentException" << endl; }
};

class ChildException : public ParentException
{
public:
	void display() { cout << "ChildException" << endl; }
};

int main()
{
	try {
		throw ChildException();
	} 
	catch (ParentException& e) 
	{
		e.display();
	}
	catch (ChildException& e) 
	{
		e.display();
	}
	return 0;
}
```

코드에서는 분명히 ChildException 클래스의 객체를 생성하여 던졌지만 catch문에서는 ParentException만 잡히게 된다. 그 이유는 다형성 개념에 의해서 ParentException도 ChildException이 될 수 있기 때문이다. 따라서 catch문에서는 자식 클래스의 레퍼런스를 더 위에 배치하는 것이 일반적이다.